08:56:31:| can only concatenate str (not "float") to str
Message:/new_hirn
Except:Traceback (most recent call last):
  File "C:\Users\lachl\Repos\GitHub\SignalSpawner\telebagger.py", line 205, in handle_new_telegram_event
    await self.handle_new_message(signal_message)
  File "C:\Users\lachl\Repos\GitHub\SignalSpawner\telebagger.py", line 238, in handle_new_message
    await self.telegram_command(signal_message)
  File "C:\Users\lachl\Repos\GitHub\SignalSpawner\telebagger.py", line 115, in telegram_command
    await self.handle_new_message(signal_message)
  File "C:\Users\lachl\Repos\GitHub\SignalSpawner\telebagger.py", line 231, in handle_new_message
    db.realtime_signal_logs(logs)
  File "C:\Users\lachl\Repos\GitHub\SignalSpawner\database_logging.py", line 91, in realtime_signal_logs
    genlog_filepath = paths.LOG + date_formatted + '/signal_logging/' + timestamp
TypeError: can only concatenate str (not "float") to str


08:56:52:| [Errno 400 Client Error: Bad Request for url: https://telebagger-default-rtdb.firebaseio.com/logs/18-Jun-23/signal_logging/1687078612.497159.json] {
  "error" : "Invalid path: Invalid token in path"
}

Message:/new_hirn
Except:Traceback (most recent call last):
  File "C:\Users\lachl\Repos\GitHub\SignalSpawner\.venv\lib\site-packages\pyrebase\pyrebase.py", line 512, in raise_detailed_error
    request_object.raise_for_status()
  File "C:\Users\lachl\Repos\GitHub\SignalSpawner\.venv\lib\site-packages\requests\models.py", line 943, in raise_for_status
    raise HTTPError(http_error_msg, response=self)
requests.exceptions.HTTPError: 400 Client Error: Bad Request for url: https://telebagger-default-rtdb.firebaseio.com/logs/18-Jun-23/signal_logging/1687078612.497159.json

During handling of the above exception, another exception occurred:

Traceback (most recent call last):
  File "C:\Users\lachl\Repos\GitHub\SignalSpawner\telebagger.py", line 205, in handle_new_telegram_event
    await self.handle_new_message(signal_message)
  File "C:\Users\lachl\Repos\GitHub\SignalSpawner\telebagger.py", line 238, in handle_new_message
    await self.telegram_command(signal_message)
  File "C:\Users\lachl\Repos\GitHub\SignalSpawner\telebagger.py", line 115, in telegram_command
    await self.handle_new_message(signal_message)
  File "C:\Users\lachl\Repos\GitHub\SignalSpawner\telebagger.py", line 231, in handle_new_message
    db.realtime_signal_logs(logs)
  File "C:\Users\lachl\Repos\GitHub\SignalSpawner\database_logging.py", line 93, in realtime_signal_logs
    add_to_realtime(genlog_filepath, msg)
  File "C:\Users\lachl\Repos\GitHub\SignalSpawner\database_logging.py", line 113, in add_to_realtime
    database.child(pathway).update(existing_data)
  File "C:\Users\lachl\Repos\GitHub\SignalSpawner\.venv\lib\site-packages\pyrebase\pyrebase.py", line 326, in update
    raise_detailed_error(request_object)
  File "C:\Users\lachl\Repos\GitHub\SignalSpawner\.venv\lib\site-packages\pyrebase\pyrebase.py", line 516, in raise_detailed_error
    raise HTTPError(e, request_object.text)
requests.exceptions.HTTPError: [Errno 400 Client Error: Bad Request for url: https://telebagger-default-rtdb.firebaseio.com/logs/18-Jun-23/signal_logging/1687078612.497159.json] {
  "error" : "Invalid path: Invalid token in path"
}



08:58:26:| [Errno 400 Client Error: Bad Request for url: https://telebagger-default-rtdb.firebaseio.com/logs/18-Jun-23/signal_logging/1687078705.json] {
  "error" : "Invalid data; couldn't parse JSON object. Are you sending a JSON object with valid key names?"
}

Message:/new_hirn
Except:Traceback (most recent call last):
  File "C:\Users\lachl\Repos\GitHub\SignalSpawner\.venv\lib\site-packages\pyrebase\pyrebase.py", line 512, in raise_detailed_error
    request_object.raise_for_status()
  File "C:\Users\lachl\Repos\GitHub\SignalSpawner\.venv\lib\site-packages\requests\models.py", line 943, in raise_for_status
    raise HTTPError(http_error_msg, response=self)
requests.exceptions.HTTPError: 400 Client Error: Bad Request for url: https://telebagger-default-rtdb.firebaseio.com/logs/18-Jun-23/signal_logging/1687078705.json

During handling of the above exception, another exception occurred:

Traceback (most recent call last):
  File "C:\Users\lachl\Repos\GitHub\SignalSpawner\telebagger.py", line 205, in handle_new_telegram_event
    await self.handle_new_message(signal_message)
  File "C:\Users\lachl\Repos\GitHub\SignalSpawner\telebagger.py", line 238, in handle_new_message
    await self.telegram_command(signal_message)
  File "C:\Users\lachl\Repos\GitHub\SignalSpawner\telebagger.py", line 115, in telegram_command
    await self.handle_new_message(signal_message)
  File "C:\Users\lachl\Repos\GitHub\SignalSpawner\telebagger.py", line 231, in handle_new_message
    db.realtime_signal_logs(logs)
  File "C:\Users\lachl\Repos\GitHub\SignalSpawner\database_logging.py", line 93, in realtime_signal_logs
    add_to_realtime(genlog_filepath, msg)
  File "C:\Users\lachl\Repos\GitHub\SignalSpawner\database_logging.py", line 113, in add_to_realtime
    database.child(pathway).update(existing_data)
  File "C:\Users\lachl\Repos\GitHub\SignalSpawner\.venv\lib\site-packages\pyrebase\pyrebase.py", line 326, in update
    raise_detailed_error(request_object)
  File "C:\Users\lachl\Repos\GitHub\SignalSpawner\.venv\lib\site-packages\pyrebase\pyrebase.py", line 516, in raise_detailed_error
    raise HTTPError(e, request_object.text)
requests.exceptions.HTTPError: [Errno 400 Client Error: Bad Request for url: https://telebagger-default-rtdb.firebaseio.com/logs/18-Jun-23/signal_logging/1687078705.json] {
  "error" : "Invalid data; couldn't parse JSON object. Are you sending a JSON object with valid key names?"
}



15:57:27:| division by zero
Message:/predictum
Except:Traceback (most recent call last):
  File "C:\Users\lachl\Repos\GitHub\SignalSpawner\telebagger.py", line 232, in handle_new_telegram_event
    await self.handle_new_message(signal_message)
  File "C:\Users\lachl\Repos\GitHub\SignalSpawner\telebagger.py", line 265, in handle_new_message
    await self.telegram_command(signal_message)
  File "C:\Users\lachl\Repos\GitHub\SignalSpawner\telebagger.py", line 181, in telegram_command
    await self.handle_new_message(signal_message)
  File "C:\Users\lachl\Repos\GitHub\SignalSpawner\telebagger.py", line 260, in handle_new_message
    if await self.is_duplicate(signal_message.origin.id, signal_message.message):
  File "C:\Users\lachl\Repos\GitHub\SignalSpawner\telebagger.py", line 95, in is_duplicate
    similarity = self.shared_chars(last_message, message_content)
  File "C:\Users\lachl\Repos\GitHub\SignalSpawner\telebagger.py", line 86, in shared_chars
    percentage_shared = (len(str1)-diff_count)/(len(str1))*100
ZeroDivisionError: division by zero


15:59:14:| division by zero
Message:/predictum
Except:Traceback (most recent call last):
  File "C:\Users\lachl\Repos\GitHub\SignalSpawner\telebagger.py", line 235, in handle_new_telegram_event
    await self.handle_new_message(signal_message)
  File "C:\Users\lachl\Repos\GitHub\SignalSpawner\telebagger.py", line 268, in handle_new_message
    await self.telegram_command(signal_message)
  File "C:\Users\lachl\Repos\GitHub\SignalSpawner\telebagger.py", line 184, in telegram_command
    await self.handle_new_message(signal_message)
  File "C:\Users\lachl\Repos\GitHub\SignalSpawner\telebagger.py", line 263, in handle_new_message
    if await self.is_duplicate(signal_message.origin.id, signal_message.message):
  File "C:\Users\lachl\Repos\GitHub\SignalSpawner\telebagger.py", line 98, in is_duplicate
    similarity = self.shared_chars(last_message, message_content)
  File "C:\Users\lachl\Repos\GitHub\SignalSpawner\telebagger.py", line 90, in shared_chars
    percentage_shared = (len(str1)-diff_count)/(len(str1))*100
ZeroDivisionError: division by zero


16:00:23:| local variable 'percentage_shared' referenced before assignment
Message:/predictum
Except:Traceback (most recent call last):
  File "C:\Users\lachl\Repos\GitHub\SignalSpawner\telebagger.py", line 236, in handle_new_telegram_event
    await self.handle_new_message(signal_message)
  File "C:\Users\lachl\Repos\GitHub\SignalSpawner\telebagger.py", line 269, in handle_new_message
    await self.telegram_command(signal_message)
  File "C:\Users\lachl\Repos\GitHub\SignalSpawner\telebagger.py", line 185, in telegram_command
    await self.handle_new_message(signal_message)
  File "C:\Users\lachl\Repos\GitHub\SignalSpawner\telebagger.py", line 264, in handle_new_message
    if await self.is_duplicate(signal_message.origin.id, signal_message.message):
  File "C:\Users\lachl\Repos\GitHub\SignalSpawner\telebagger.py", line 99, in is_duplicate
    similarity = self.shared_chars(last_message, message_content)
  File "C:\Users\lachl\Repos\GitHub\SignalSpawner\telebagger.py", line 92, in shared_chars
    print(percentage_shared)
UnboundLocalError: local variable 'percentage_shared' referenced before assignment


16:17:56:| local variable 'max' referenced before assignment
Message:/predictum
Except:Traceback (most recent call last):
  File "C:\Users\lachl\Repos\GitHub\SignalSpawner\telebagger.py", line 228, in handle_new_telegram_event
    await self.handle_new_message(signal_message)
  File "C:\Users\lachl\Repos\GitHub\SignalSpawner\telebagger.py", line 261, in handle_new_message
    await self.telegram_command(signal_message)
  File "C:\Users\lachl\Repos\GitHub\SignalSpawner\telebagger.py", line 177, in telegram_command
    await self.handle_new_message(signal_message)
  File "C:\Users\lachl\Repos\GitHub\SignalSpawner\telebagger.py", line 256, in handle_new_message
    if await self.is_duplicate(signal_message.origin.id, signal_message.message):
  File "C:\Users\lachl\Repos\GitHub\SignalSpawner\telebagger.py", line 91, in is_duplicate
    similarity = self.shared_chars(last_message, message_content)
  File "C:\Users\lachl\Repos\GitHub\SignalSpawner\telebagger.py", line 82, in shared_chars
    max = max(str1, str2)
UnboundLocalError: local variable 'max' referenced before assignment


16:18:42:| unsupported operand type(s) for /: 'int' and 'str'
Message:/predictum
Except:Traceback (most recent call last):
  File "C:\Users\lachl\Repos\GitHub\SignalSpawner\telebagger.py", line 228, in handle_new_telegram_event
    await self.handle_new_message(signal_message)
  File "C:\Users\lachl\Repos\GitHub\SignalSpawner\telebagger.py", line 261, in handle_new_message
    await self.telegram_command(signal_message)
  File "C:\Users\lachl\Repos\GitHub\SignalSpawner\telebagger.py", line 177, in telegram_command
    await self.handle_new_message(signal_message)
  File "C:\Users\lachl\Repos\GitHub\SignalSpawner\telebagger.py", line 256, in handle_new_message
    if await self.is_duplicate(signal_message.origin.id, signal_message.message):
  File "C:\Users\lachl\Repos\GitHub\SignalSpawner\telebagger.py", line 91, in is_duplicate
    similarity = self.shared_chars(last_message, message_content)
  File "C:\Users\lachl\Repos\GitHub\SignalSpawner\telebagger.py", line 84, in shared_chars
    print(shared/length*100)
TypeError: unsupported operand type(s) for /: 'int' and 'str'


