16:53:35:| SIGNAL_GROUPS
Message:/newchannel 1086571621969563648 cryptosignals-general ignore
Except:Traceback (most recent call last):
  File "C:\Users\lachl\Repos\GitHub\telebagger\.venv\lib\site-packages\munch\__init__.py", line 103, in __getattr__
    return object.__getattribute__(self, k)
AttributeError: 'Munch' object has no attribute 'SIGNAL_GROUPS'

During handling of the above exception, another exception occurred:

Traceback (most recent call last):
  File "C:\Users\lachl\Repos\GitHub\telebagger\.venv\lib\site-packages\munch\__init__.py", line 106, in __getattr__
    return self[k]
KeyError: 'SIGNAL_GROUPS'

During handling of the above exception, another exception occurred:

Traceback (most recent call last):
  File "C:\Users\lachl\Repos\GitHub\telebagger\telebagger.py", line 146, in my_event_handler
    if signal.origin.id in self.com.SIGNAL_GROUPS:
  File "C:\Users\lachl\Repos\GitHub\telebagger\.venv\lib\site-packages\munch\__init__.py", line 108, in __getattr__
    raise AttributeError(k)
AttributeError: SIGNAL_GROUPS


16:54:11:| SIGNAL_GROUPS
Message:/stop
Except:Traceback (most recent call last):
  File "C:\Users\lachl\Repos\GitHub\telebagger\.venv\lib\site-packages\munch\__init__.py", line 103, in __getattr__
    return object.__getattribute__(self, k)
AttributeError: 'Munch' object has no attribute 'SIGNAL_GROUPS'

During handling of the above exception, another exception occurred:

Traceback (most recent call last):
  File "C:\Users\lachl\Repos\GitHub\telebagger\.venv\lib\site-packages\munch\__init__.py", line 106, in __getattr__
    return self[k]
KeyError: 'SIGNAL_GROUPS'

During handling of the above exception, another exception occurred:

Traceback (most recent call last):
  File "C:\Users\lachl\Repos\GitHub\telebagger\telebagger.py", line 146, in my_event_handler
    if signal.origin.id in self.com.SIGNAL_GROUP:
  File "C:\Users\lachl\Repos\GitHub\telebagger\.venv\lib\site-packages\munch\__init__.py", line 108, in __getattr__
    raise AttributeError(k)
AttributeError: SIGNAL_GROUPS


17:13:44:| 'NoneType' object is not iterable
Message:/get discord_signals
Except:Traceback (most recent call last):
  File "C:\Users\lachl\Repos\GitHub\telebagger\telebagger.py", line 150, in my_event_handler
    await self.telegram_command(signal)
  File "C:\Users\lachl\Repos\GitHub\telebagger\telebagger.py", line 126, in telegram_command
    db.get_from_realtime(signal.message.split('/get ')[1])
  File "C:\Users\lachl\Repos\GitHub\telebagger\database_logging.py", line 244, in get_from_realtime
    for user in data.each():
TypeError: 'NoneType' object is not iterable


17:36:10:| 'function' object has no attribute 'val'
Message:/newchannel 1086577011423711262 cryptosignals-cryptosignals signal
Except:Traceback (most recent call last):
  File "C:\Users\lachl\Repos\GitHub\telebagger\telebagger.py", line 155, in my_event_handler
    await self.telegram_command(signal)
  File "C:\Users\lachl\Repos\GitHub\telebagger\telebagger.py", line 139, in telegram_command
    db.add_discord_channel(channel_id, channel_name, channel_category)
  File "C:\Users\lachl\Repos\GitHub\telebagger\database_logging.py", line 261, in add_discord_channel
    add_to_realtime(paths.DISCORD_CHANNEL +f"/{category}", data)
  File "C:\Users\lachl\Repos\GitHub\telebagger\database_logging.py", line 250, in add_to_realtime
    existing_data = database.child(pathway).get.val()
AttributeError: 'function' object has no attribute 'val'


19:28:07:| list index out of range
Message:/newchannel 1055528388397379704 cryptosignals-spotsignals
Except:Traceback (most recent call last):
  File "C:\Users\lachl\Repos\GitHub\telebagger\telebagger.py", line 154, in my_event_handler
    await self.telegram_command(signal)
  File "C:\Users\lachl\Repos\GitHub\telebagger\telebagger.py", line 135, in telegram_command
    channel_id, channel_name, channel_category = channelinfo[1], channelinfo[2], channelinfo[3]
IndexError: list index out of range


19:29:16:| 'NoneType' object has no attribute 'update'
Message:/newchannel 1038975657482395801 cryptosignals-general ignore
Except:Traceback (most recent call last):
  File "C:\Users\lachl\Repos\GitHub\telebagger\telebagger.py", line 154, in my_event_handler
    await self.telegram_command(signal)
  File "C:\Users\lachl\Repos\GitHub\telebagger\telebagger.py", line 139, in telegram_command
    db.add_discord_channel(channel_id, channel_name, channel_category)
  File "C:\Users\lachl\Repos\GitHub\telebagger\database_logging.py", line 261, in add_discord_channel
    add_to_realtime(paths.DISCORD_CHANNEL +f"/{category}", data)
  File "C:\Users\lachl\Repos\GitHub\telebagger\database_logging.py", line 251, in add_to_realtime
    existing_data.update(data)
AttributeError: 'NoneType' object has no attribute 'update'


19:35:11:| list index out of range
Message:/newchannel 1057322668698906704 cryptosignals-cryptosignals
Except:Traceback (most recent call last):
  File "C:\Users\lachl\Repos\GitHub\telebagger\telebagger.py", line 154, in my_event_handler
    await self.telegram_command(signal)
  File "C:\Users\lachl\Repos\GitHub\telebagger\telebagger.py", line 135, in telegram_command
    channel_id, channel_name, channel_category = channelinfo[1], channelinfo[2], channelinfo[3]
IndexError: list index out of range


