20:24:19:| 'str' object does not support item assignment
Message:/last_week!
Except:Traceback (most recent call last):
  File "C:\Users\lachl\Repos\GitHub\SignalSpawner\telebagger.py", line 193, in my_event_handler
    await self.telegram_command(signal_message)
  File "C:\Users\lachl\Repos\GitHub\SignalSpawner\telebagger.py", line 164, in telegram_command
    db.generate_last_week_signals()
  File "C:\Users\lachl\Repos\GitHub\SignalSpawner\database_logging.py", line 287, in generate_last_week_signals
    trade = handle_signal_message.trade_from_signal_data(inner_value, True)
  File "C:\Users\lachl\Repos\GitHub\SignalSpawner\handle_signal_message.py", line 39, in trade_from_signal_data
    return trade_from_signal(signal_from_signal_data(signal_data), filter)
  File "C:\Users\lachl\Repos\GitHub\SignalSpawner\handle_signal_message.py", line 45, in signal_from_signal_data
    signal = Signal(signal_data.source, signal_data.message, signal_data.coin, signal_data.base, signal_data.entry, signal_data.take_profit, signal_data.stop_loss, signal_data.direction)
  File "C:\Users\lachl\Repos\GitHub\SignalSpawner\signal_conditions.py", line 30, in __init__
    self.convert_price_data_float()
  File "C:\Users\lachl\Repos\GitHub\SignalSpawner\signal_conditions.py", line 71, in convert_price_data_float
    self.entry[i] = float(self.entry[i])
TypeError: 'str' object does not support item assignment


20:27:07:| [Errno 400 Client Error: Bad Request for url: https://telebagger-default-rtdb.firebaseio.com/heroku/raw_signals//Hirn/1684671215910.json] {
  "error" : "Invalid data; couldn't parse key beginning at 1:442. Key value can't be empty or contain $ # [ ] / or ."
}

Message:/change_value!
Except:Traceback (most recent call last):
  File "C:\Users\lachl\Repos\GitHub\SignalSpawner\.venv\lib\site-packages\pyrebase\pyrebase.py", line 512, in raise_detailed_error
    request_object.raise_for_status()
  File "C:\Users\lachl\Repos\GitHub\SignalSpawner\.venv\lib\site-packages\requests\models.py", line 943, in raise_for_status
    raise HTTPError(http_error_msg, response=self)
requests.exceptions.HTTPError: 400 Client Error: Bad Request for url: https://telebagger-default-rtdb.firebaseio.com/heroku/raw_signals//Hirn/1684671215910.json

During handling of the above exception, another exception occurred:

Traceback (most recent call last):
  File "C:\Users\lachl\Repos\GitHub\SignalSpawner\telebagger.py", line 193, in my_event_handler
    await self.telegram_command(signal_message)
  File "C:\Users\lachl\Repos\GitHub\SignalSpawner\telebagger.py", line 168, in telegram_command
    db.change_database_value()
  File "C:\Users\lachl\Repos\GitHub\SignalSpawner\database_logging.py", line 341, in change_database_value
    database.child(path).child(outer_key).child(inner_key).set(inner_value)
  File "C:\Users\lachl\Repos\GitHub\SignalSpawner\.venv\lib\site-packages\pyrebase\pyrebase.py", line 318, in set
    raise_detailed_error(request_object)
  File "C:\Users\lachl\Repos\GitHub\SignalSpawner\.venv\lib\site-packages\pyrebase\pyrebase.py", line 516, in raise_detailed_error
    raise HTTPError(e, request_object.text)
requests.exceptions.HTTPError: [Errno 400 Client Error: Bad Request for url: https://telebagger-default-rtdb.firebaseio.com/heroku/raw_signals//Hirn/1684671215910.json] {
  "error" : "Invalid data; couldn't parse key beginning at 1:442. Key value can't be empty or contain $ # [ ] / or ."
}



20:30:18:| [Errno 400 Client Error: Bad Request for url: https://telebagger-default-rtdb.firebaseio.com/heroku/raw_signals//Hirn/1684671215910.json] {
  "error" : "Invalid data; couldn't parse key beginning at 1:442. Key value can't be empty or contain $ # [ ] / or ."
}

Message:/change_value!
Except:Traceback (most recent call last):
  File "C:\Users\lachl\Repos\GitHub\SignalSpawner\.venv\lib\site-packages\pyrebase\pyrebase.py", line 512, in raise_detailed_error
    request_object.raise_for_status()
  File "C:\Users\lachl\Repos\GitHub\SignalSpawner\.venv\lib\site-packages\requests\models.py", line 943, in raise_for_status
    raise HTTPError(http_error_msg, response=self)
requests.exceptions.HTTPError: 400 Client Error: Bad Request for url: https://telebagger-default-rtdb.firebaseio.com/heroku/raw_signals//Hirn/1684671215910.json

During handling of the above exception, another exception occurred:

Traceback (most recent call last):
  File "C:\Users\lachl\Repos\GitHub\SignalSpawner\telebagger.py", line 193, in my_event_handler
    await self.telegram_command(signal_message)
  File "C:\Users\lachl\Repos\GitHub\SignalSpawner\telebagger.py", line 168, in telegram_command
    db.change_database_value()
  File "C:\Users\lachl\Repos\GitHub\SignalSpawner\database_logging.py", line 341, in change_database_value
    database.child(path).child(outer_key).child(inner_key).set(inner_value)
  File "C:\Users\lachl\Repos\GitHub\SignalSpawner\.venv\lib\site-packages\pyrebase\pyrebase.py", line 318, in set
    raise_detailed_error(request_object)
  File "C:\Users\lachl\Repos\GitHub\SignalSpawner\.venv\lib\site-packages\pyrebase\pyrebase.py", line 516, in raise_detailed_error
    raise HTTPError(e, request_object.text)
requests.exceptions.HTTPError: [Errno 400 Client Error: Bad Request for url: https://telebagger-default-rtdb.firebaseio.com/heroku/raw_signals//Hirn/1684671215910.json] {
  "error" : "Invalid data; couldn't parse key beginning at 1:442. Key value can't be empty or contain $ # [ ] / or ."
}



22:28:14:| 'FutureBasic' object has no attribute 'source'
Message:/last_week!
Except:Traceback (most recent call last):
  File "C:\Users\lachl\Repos\GitHub\SignalSpawner\telebagger.py", line 193, in my_event_handler
    await self.telegram_command(signal_message)
  File "C:\Users\lachl\Repos\GitHub\SignalSpawner\telebagger.py", line 164, in telegram_command
    db.generate_last_week_signals()
  File "C:\Users\lachl\Repos\GitHub\SignalSpawner\database_logging.py", line 289, in generate_last_week_signals
    trade.run_backtest()
  File "C:\Users\lachl\Repos\GitHub\SignalSpawner\trade_conditions.py", line 80, in run_backtest
    self.backtest = backtesting.run_backtest_from_trade(self)
  File "C:\Users\lachl\Repos\GitHub\SignalSpawner\backtesting.py", line 278, in run_backtest_from_trade
    if trade.source == 'hirn':
AttributeError: 'FutureBasic' object has no attribute 'source'


22:29:20:| 'FutureBasic' object has no attribute 'source'
Message:/last_week!
Except:Traceback (most recent call last):
  File "C:\Users\lachl\Repos\GitHub\SignalSpawner\telebagger.py", line 193, in my_event_handler
    await self.telegram_command(signal_message)
  File "C:\Users\lachl\Repos\GitHub\SignalSpawner\telebagger.py", line 164, in telegram_command
    db.generate_last_week_signals()
  File "C:\Users\lachl\Repos\GitHub\SignalSpawner\database_logging.py", line 289, in generate_last_week_signals
    trade.run_backtest()
  File "C:\Users\lachl\Repos\GitHub\SignalSpawner\trade_conditions.py", line 80, in run_backtest
    self.backtest = backtesting.run_backtest_from_trade(self)
  File "C:\Users\lachl\Repos\GitHub\SignalSpawner\backtesting.py", line 279, in run_backtest_from_trade
    if trade.source == 'hirn':
AttributeError: 'FutureBasic' object has no attribute 'source'


22:29:49:| 'FutureBasic' object has no attribute 'message'
Message:/last_week!
Except:Traceback (most recent call last):
  File "C:\Users\lachl\Repos\GitHub\SignalSpawner\telebagger.py", line 193, in my_event_handler
    await self.telegram_command(signal_message)
  File "C:\Users\lachl\Repos\GitHub\SignalSpawner\telebagger.py", line 164, in telegram_command
    db.generate_last_week_signals()
  File "C:\Users\lachl\Repos\GitHub\SignalSpawner\database_logging.py", line 289, in generate_last_week_signals
    trade.run_backtest()
  File "C:\Users\lachl\Repos\GitHub\SignalSpawner\trade_conditions.py", line 80, in run_backtest
    self.backtest = backtesting.run_backtest_from_trade(self)
  File "C:\Users\lachl\Repos\GitHub\SignalSpawner\backtesting.py", line 279, in run_backtest_from_trade
    if trade.message.source == 'hirn':
AttributeError: 'FutureBasic' object has no attribute 'message'


