08:32:36:| Cannot find any entity corresponding to "1548802426"
Message:/past
Except:Traceback (most recent call last):
  File "C:\Users\lachl\Repos\GitHub\telebagger\telebagger.py", line 119, in my_event_handler
    await self.telegram_command(signal)
  File "C:\Users\lachl\Repos\GitHub\telebagger\telebagger.py", line 100, in telegram_command
    await self.get_past_messages('1548802426')
  File "C:\Users\lachl\Repos\GitHub\telebagger\telebagger.py", line 47, in get_past_messages
    msgs = await self.client.get_messages(channel_id, limit=10)
  File "C:\Users\lachl\Repos\GitHub\telebagger\.venv\lib\site-packages\telethon\client\messages.py", line 586, in get_messages
    return await it.collect()
  File "C:\Users\lachl\Repos\GitHub\telebagger\.venv\lib\site-packages\telethon\requestiter.py", line 113, in collect
    async for message in self:
  File "C:\Users\lachl\Repos\GitHub\telebagger\.venv\lib\site-packages\telethon\requestiter.py", line 58, in __anext__
    if await self._init(**self.kwargs):
  File "C:\Users\lachl\Repos\GitHub\telebagger\.venv\lib\site-packages\telethon\client\messages.py", line 27, in _init
    self.entity = await self.client.get_input_entity(entity)
  File "C:\Users\lachl\Repos\GitHub\telebagger\.venv\lib\site-packages\telethon\client\users.py", line 437, in get_input_entity
    await self._get_entity_from_string(peer))
  File "C:\Users\lachl\Repos\GitHub\telebagger\.venv\lib\site-packages\telethon\client\users.py", line 574, in _get_entity_from_string
    raise ValueError(
ValueError: Cannot find any entity corresponding to "1548802426"


08:33:27:| Cannot find any entity corresponding to "1248393106"
Message:/past
Except:Traceback (most recent call last):
  File "C:\Users\lachl\Repos\GitHub\telebagger\telebagger.py", line 119, in my_event_handler
    await self.telegram_command(signal)
  File "C:\Users\lachl\Repos\GitHub\telebagger\telebagger.py", line 100, in telegram_command
    await self.get_past_messages('1248393106')
  File "C:\Users\lachl\Repos\GitHub\telebagger\telebagger.py", line 47, in get_past_messages
    msgs = await self.client.get_messages(channel_id, limit=10)
  File "C:\Users\lachl\Repos\GitHub\telebagger\.venv\lib\site-packages\telethon\client\messages.py", line 586, in get_messages
    return await it.collect()
  File "C:\Users\lachl\Repos\GitHub\telebagger\.venv\lib\site-packages\telethon\requestiter.py", line 113, in collect
    async for message in self:
  File "C:\Users\lachl\Repos\GitHub\telebagger\.venv\lib\site-packages\telethon\requestiter.py", line 58, in __anext__
    if await self._init(**self.kwargs):
  File "C:\Users\lachl\Repos\GitHub\telebagger\.venv\lib\site-packages\telethon\client\messages.py", line 27, in _init
    self.entity = await self.client.get_input_entity(entity)
  File "C:\Users\lachl\Repos\GitHub\telebagger\.venv\lib\site-packages\telethon\client\users.py", line 437, in get_input_entity
    await self._get_entity_from_string(peer))
  File "C:\Users\lachl\Repos\GitHub\telebagger\.venv\lib\site-packages\telethon\client\users.py", line 574, in _get_entity_from_string
    raise ValueError(
ValueError: Cannot find any entity corresponding to "1248393106"


08:34:42:| Cannot find any entity corresponding to "1248393106"
Message:/past
Except:Traceback (most recent call last):
  File "C:\Users\lachl\Repos\GitHub\telebagger\telebagger.py", line 120, in my_event_handler
    await self.telegram_command(signal)
  File "C:\Users\lachl\Repos\GitHub\telebagger\telebagger.py", line 101, in telegram_command
    await self.get_past_messages('1248393106')
  File "C:\Users\lachl\Repos\GitHub\telebagger\telebagger.py", line 47, in get_past_messages
    msgs = await self.client.get_messages(channel_id, limit=10)
  File "C:\Users\lachl\Repos\GitHub\telebagger\.venv\lib\site-packages\telethon\client\messages.py", line 586, in get_messages
    return await it.collect()
  File "C:\Users\lachl\Repos\GitHub\telebagger\.venv\lib\site-packages\telethon\requestiter.py", line 113, in collect
    async for message in self:
  File "C:\Users\lachl\Repos\GitHub\telebagger\.venv\lib\site-packages\telethon\requestiter.py", line 58, in __anext__
    if await self._init(**self.kwargs):
  File "C:\Users\lachl\Repos\GitHub\telebagger\.venv\lib\site-packages\telethon\client\messages.py", line 27, in _init
    self.entity = await self.client.get_input_entity(entity)
  File "C:\Users\lachl\Repos\GitHub\telebagger\.venv\lib\site-packages\telethon\client\users.py", line 437, in get_input_entity
    await self._get_entity_from_string(peer))
  File "C:\Users\lachl\Repos\GitHub\telebagger\.venv\lib\site-packages\telethon\client\users.py", line 574, in _get_entity_from_string
    raise ValueError(
ValueError: Cannot find any entity corresponding to "1248393106"


08:35:22:| Cannot find any entity corresponding to "1248393106"
Message:/past
Except:Traceback (most recent call last):
  File "C:\Users\lachl\Repos\GitHub\telebagger\telebagger.py", line 120, in my_event_handler
    await self.telegram_command(signal)
  File "C:\Users\lachl\Repos\GitHub\telebagger\telebagger.py", line 101, in telegram_command
    await self.get_past_messages('1248393106')
  File "C:\Users\lachl\Repos\GitHub\telebagger\telebagger.py", line 47, in get_past_messages
    msgs = await self.client.get_messages(str(channel_id), limit=10)
  File "C:\Users\lachl\Repos\GitHub\telebagger\.venv\lib\site-packages\telethon\client\messages.py", line 586, in get_messages
    return await it.collect()
  File "C:\Users\lachl\Repos\GitHub\telebagger\.venv\lib\site-packages\telethon\requestiter.py", line 113, in collect
    async for message in self:
  File "C:\Users\lachl\Repos\GitHub\telebagger\.venv\lib\site-packages\telethon\requestiter.py", line 58, in __anext__
    if await self._init(**self.kwargs):
  File "C:\Users\lachl\Repos\GitHub\telebagger\.venv\lib\site-packages\telethon\client\messages.py", line 27, in _init
    self.entity = await self.client.get_input_entity(entity)
  File "C:\Users\lachl\Repos\GitHub\telebagger\.venv\lib\site-packages\telethon\client\users.py", line 437, in get_input_entity
    await self._get_entity_from_string(peer))
  File "C:\Users\lachl\Repos\GitHub\telebagger\.venv\lib\site-packages\telethon\client\users.py", line 574, in _get_entity_from_string
    raise ValueError(
ValueError: Cannot find any entity corresponding to "1248393106"


